Workbook

Sheet Por año
E1: 2025-2026
E2: LSG | H2: UC3M
B3: Materia | C3: Presentados | E3: % LSG | F3: NM LSG EvAU | G3: NM LSG Cole | H3: % UC3M | I3: NM UC3M
A4: 25-26 | B4: Lengua | C4: 54 | D4: =CONCATENATE(B4,"(",C4,")") -> Lengua(54) | E4: 0.9322 | F4: 5.37 | G4: 7.16 | H4: 0.8326 | I4: 6.5
A5: 25-26 | B5: Inglés | C5: 53 | D5: =CONCATENATE(B5,"(",C5,")") -> Inglés(53) | E5: 0.8983 | F5: 6.69 | G5: 7 | H5: 0.8447 | I5: 7.15
A6: 25-26 | B6: Historia | C6: 23 | D6: =CONCATENATE(B6,"(",C6,")") -> Historia(23) | E6: 0.3898 | F6: 6.73 | G6: 6.59 | H6: 0.8244 | I6: 6.91
A7: 25-26 | B7: Mate | C7: 38 | D7: =CONCATENATE(B7,"(",C7,")") -> Mate(38) | E7: 0.95 | F7: 5.41 | G7: 7 | H7: 0.5941 | I7: 5.47
A8: 25-26 | B8: Mate CCSS | C8: 16 | D8: =CONCATENATE(B8,"(",C8,")") -> Mate CCSS(16) | E8: 0.8421 | F8: 4.67 | G8: 6.43 | H8: 0.5923 | I8: 5.22
A9: 25-26 | B9: Física | C9: 15 | D9: =CONCATENATE(B9,"(",C9,")") -> Física(15) | E9: 0.7142 | F9: 6.53 | G9: 6.65 | H9: 0.5504 | I9: 5.3
A10: 25-26 | B10: Química | C10: 22 | D10: =CONCATENATE(B10,"(",C10,")") -> Química(22) | E10: 0.7586 | F10: 5.33 | G10: 7.05 | H10: 0.7366 | I10: 6.11
A11: 25-26 | B11: Biología | C11: 16 | D11: =CONCATENATE(B11,"(",C11,")") -> Biología(16) | E11: 0.8421 | F11: 6.3 | G11: 7.6 | H11: 0.6513 | I11: 5.64
A12: 25-26 | B12: Dibujo Técnico | C12: 2 | D12: =CONCATENATE(B12,"(",C12,")") -> Dibujo Técnico(2) | E12: 0.3333 | F12: 5.25 | G12: 9.5 | H12: 0.6677 | I12: 5.79
A13: 25-26 | B13: Economía | C13: 14 | D13: =CONCATENATE(B13,"(",C13,")") -> Economía(14) | E13: 0.7368 | F13: 6.92 | G13: 6 | H13: 0.7622 | I13: 6.22
A14: 25-26 | B14: H. Filosofía | C14: 31 | D14: =CONCATENATE(B14,"(",C14,")") -> H. Filosofía(31) | E14: 0.5254 | F14: 6.89 | G14: 7.41 | H14: 0.7621 | I14: 6.43
A15: 25-26 | B15: H. Arte | C15: 0 | D15: =CONCATENATE(B15,"(",C15,")") -> H. Arte(0) | H15: 0.6324 | I15: 5.58
A16: 25-26 | B16: Geografía | C16: 12 | D16: =CONCATENATE(B16,"(",C16,")") -> Geografía(12) | E16: 0.6315 | F16: 6.63 | G16: 7.14 | H16: 0.745 | I16: 6.23
A17: 25-26 | B17: Tecno e Ing | C17: 7 | D17: =CONCATENATE(B17,"(",C17,")") -> Tecno e Ing(7) | E17: 0.6363 | F17: 4.73 | G17: 7.73 | H17: 0.7068 | I17: 6.107
A18: 25-26 | B18: Fase General | C18: 54 | D18: =CONCATENATE(B18,"(",C18,")") -> Fase General(54) | E18: 0.973 | F18: 6.01 | G18: =(C4*G4+C5*G5+C6*G6+C7*G7+C8*G8+C14*G14)/(C4+C5+C6+C7+C8+C14) -> 7.0130233 | I18: 6.437
A19: 25-26 | B19: Titulan | C19: 56 | D19: =CONCATENATE(B19,"(",C19,")") -> Titulan(56) | E19: 0.9491
E20: 2024-2025
E21: LSG | H21: UC3M
B22: Materia | C22: Presentados | E22: % LSG | F22: NM LSG EvAU | G22: NM LSG Cole | H22: % UC3M | I22: NM UC3M
A23: 24-25 | B23: Lengua | C23: 37 | D23: =CONCATENATE(B23,"(",C23,")") -> Lengua(37) | E23: 0.7027 | F23: 5.37 | G23: 7.16 | H23: 0.8326 | I23: 6.5
A24: 24-25 | B24: Inglés | C24: 37 | D24: =CONCATENATE(B24,"(",C24,")") -> Inglés(37) | E24: 0.8378 | F24: 7.01 | G24: 7 | H24: 0.8447 | I24: 7.15
A25: 24-25 | B25: Historia | C25: 9 | D25: =CONCATENATE(B25,"(",C25,")") -> Historia(9) | E25: 0.6667 | F25: 5.89 | G25: 6.59 | H25: 0.8244 | I25: 6.91
A26: 24-25 | B26: Mate | C26: 30 | D26: =CONCATENATE(B26,"(",C26,")") -> Mate(30) | E26: 0.6333 | F26: 5.19 | G26: 7 | H26: 0.5941 | I26: 5.47
A27: 24-25 | B27: Mate CCSS | C27: 7 | D27: =CONCATENATE(B27,"(",C27,")") -> Mate CCSS(7) | E27: 1 | F27: 6.36 | G27: 6.43 | H27: 0.5923 | I27: 5.22
A28: 24-25 | B28: Física | C28: 20 | D28: =CONCATENATE(B28,"(",C28,")") -> Física(20) | E28: 0.3 | F28: 4.43 | G28: 6.65 | H28: 0.5504 | I28: 5.3
A29: 24-25 | B29: Química | C29: 15 | D29: =CONCATENATE(B29,"(",C29,")") -> Química(15) | E29: 0.8667 | F29: 6.68 | G29: 7.05 | H29: 0.7366 | I29: 6.11
A30: 24-25 | B30: Biología | C30: 11 | D30: =CONCATENATE(B30,"(",C30,")") -> Biología(11) | E30: 0.5455 | F30: 5 | G30: 7.6 | H30: 0.6513 | I30: 5.64
A31: 24-25 | B31: Dibujo Técnico | C31: 4 | D31: =CONCATENATE(B31,"(",C31,")") -> Dibujo Técnico(4) | E31: 0.25 | F31: 3.31 | G31: 9.5 | H31: 0.6677 | I31: 5.79
A32: 24-25 | B32: Economía | C32: 5 | D32: =CONCATENATE(B32,"(",C32,")") -> Economía(5) | E32: 1 | F32: 6.1 | G32: 6 | H32: 0.7622 | I32: 6.22
A33: 24-25 | B33: H. Filosofía | C33: 28 | D33: =CONCATENATE(B33,"(",C33,")") -> H. Filosofía(28) | E33: 0.75 | F33: 6.36 | G33: 7.41 | H33: 0.7621 | I33: 6.43
A34: 24-25 | B34: H. Arte | C34: 0 | D34: =CONCATENATE(B34,"(",C34,")") -> H. Arte(0) | H34: 0.6324 | I34: 5.58
A35: 24-25 | B35: Geografía | C35: 2 | D35: =CONCATENATE(B35,"(",C35,")") -> Geografía(2) | E35: 0.5 | F35: 4.88 | G35: 7.14 | H35: 0.745 | I35: 6.23
A36: 24-25 | B36: Tecno e Ing | C36: 0 | D36: =CONCATENATE(B36,"(",C36,")") -> Tecno e Ing(0) | G36: 7.73 | H36: 0.7068 | I36: 6.107
A37: 24-25 | B37: Fase General | C37: 37 | D37: =CONCATENATE(B37,"(",C37,")") -> Fase General(37) | E37: 0.973 | F37: 6.01 | G37: =(C23*G23+C24*G24+C25*G25+C26*G26+C27*G27+C33*G33)/(C23+C24+C25+C26+C27+C33) -> 7.0656757 | I37: 6.437
A38: 24-25 | B38: Titulan | C38: 52 | D38: =CONCATENATE(B38,"(",C38,")") -> Titulan(52) | E38: 0.7115
E39: 2023-2024
E40: LSG | H40: UC3M
...

Sheet Otros Coles
B3: 13/14 | G3: 14/15 | L3: 15/16 | Q3: 16/17 | V3: 17/18 | AA3: 18/19 | AF3: 19/20 | AK3: 20/21 | AP3: 21/22 | AU3: 22/23 | AZ3: 23/24 | BE3: 24/25
B4: % Titulados Bach | C4: %Aprobados EvAU | D4: Presentados EvAU | E4: Media EvAU Aprobados | F4: Media FG | G4: % Titulados Bach | H4: %Aprobados EvAU | I4: Presentados EvAU | J4: Media EvAU Aprobados | K4: Media FG | L4: % Titulados Bach | M4: %Aprobados EvAU | N4: Presentados EvAU | O4: Media EvAU Aprobados | P4: Media FG | Q4: % Titulados Bach | R4: %Aprobados EvAU | S4: Presentados EvAU | T4: Media EvAU Aprobados | U4: Media FG | V4: % Titulados Bach | W4: %Aprobados EvAU | X4: Presentados EvAU | Y4: Media EvAU Aprobados | Z4: Media FG | AA4: % Titulados Bach | AB4: %Aprobados EvAU | AC4: Presentados EvAU | AD4: Media EvAU Aprobados | AE4: Media FG | AF4: % Titulados Bach | AG4: %Aprobados EvAU | AH4: Presentados EvAU | AI4: Media EvAU Aprobados | AJ4: Media FG | AK4: % Titulados Bach | AL4: %Aprobados EvAU | AM4: Presentados EvAU | AN4: Media EvAU Aprobados | AO4: Media FG | AP4: % Titulados Bach | AQ4: %Aprobados EvAU | AR4: Presentados EvAU | AS4: Media EvAU Aprobados | AT4: Media FG | AU4: % Titulados Bach | AV4: %Aprobados EvAU | AW4: Presentados EvAU | AX4: Media EvAU Aprobados | AY4: Media FG | AZ4: % Titulados Bach | BA4: %Aprobados EvAU | BB4: Presentados EvAU | BC4: Media EvAU Aprobados | BD4: Media FG | BE4: % Titulados Bach | BF4: %Aprobados EvAU | BG4: Presentados EvAU | BH4: Media EvAU Aprobados | BI4: Media FG
B5: 13/14 | C5: 13/14 | D5: 13/14 | E5: 13/14 | F5: 13/14 | G5: 14/15 | H5: 14/15 | I5: 14/15 | J5: 14/15 | K5: 14/15 | L5: 15/16 | M5: 15/16 | N5: 15/16 | O5: 15/16 | P5: 15/16 | Q5: 16/17 | R5: 16/17 | S5: 16/17 | T5: 16/17 | U5: 16/17 | V5: 17/18 | W5: 17/18 | X5: 17/18 | Y5: 17/18 | Z5: 17/18 | AA5: 18/19 | AB5: 18/19 | AC5: 18/19 | AD5: 18/19 | AE5: 18/19 | AF5: 19/20 | AG5: 19/20 | AH5: 19/20 | AI5: 19/20 | AJ5: 19/20 | AK5: 20/21 | AL5: 20/21 | AM5: 20/21 | AN5: 20/21 | AO5: 20/21 | AP5: 21/22 | AQ5: 21/22 | AR5: 21/22 | AS5: 21/22 | AT5: 21/22 | AU5: 22/23 | AV5: 22/23 | AW5: 22/23 | AX5: 22/23 | AY5: 22/23 | AZ5: 23/24 | BA5: 23/24 | BB5: 23/24 | BC5: 23/24 | BD5: 23/24 | BE5: 24/25 | BF5: 24/25 | BG5: 24/25 | BH5: 24/25 | BI5: 24/25
A6: CAM | B6: 76.96 | C6: 94.15 | D6: 0 | E6: 6.98 | F6: 6.22 | G6: 76.73 | H6: 93.8 | I6: 0 | J6: 6.57 | K6: 6.37 | L6: 78.67 | M6: 94.16 | O6: 6.5 | P6: 6.32 | Q6: 79.72 | R6: 91.53 | T6: 6.57 | U6: 6.29 | V6: 80.16 | W6: 93.79 | Y6: 7.28 | Z6: 6.45 | AA6: 73.42 | AB6: 85.71 | AD6: 7.19 | AE6: 6.27 | AF6: 86.16 | AG6: 100 | AI6: 7.34 | AJ6: 6.51 | AK6: 75.87 | AL6: 66.67 | AN6: 7.42 | AO6: 6.51 | AP6: 80.35 | AQ6: 93.11 | AS6: 7.41 | AT6: 6.49 | AU6: 84.17 | AV6: 95.04 | AX6: 7.5 | AY6: 6.76 | AZ6: 85.77 | BA6: 95.03 | BC6: 7.41 | BD6: 6.68
A7: LSG | B7: 75 | C7: 100 | D7: 26 | E7: 6.83 | F7: 6.61 | G7: 87.5 | H7: 100 | I7: 28 | J7: 6.71 | K7: 6.71 | L7: 95.24 | M7: 96.97 | N7: 33 | O7: 6.14 | P7: 6.06 | Q7: 88.89 | R7: 94.29 | S7: 35 | T7: 6.17 | U7: 6 | V7: 88.64 | W7: 93.55 | X7: 31 | Y7: 6.8 | Z7: 5.99 | AB7: 95.65 | AC7: 46 | AD7: 6.7 | AE7: 5.88 | AG7: 87.5 | AH7: 56 | AI7: 7.39 | AJ7: 6.29 | AL7: 96.15 | AM7: 52 | AN7: 6.93 | AO7: 5.86 | AQ7: 86.89 | AR7: 61 | AS7: 7.2 | AT7: 6.03 | AU7: 94.34 | AV7: 90.38 | AW7: 52 | AX7: 7.22 | AY7: 6.24 | AZ7: 84.48 | BA7: 87.27 | BB7: 55 | BC7: 6.79 | BD7: 5.6
A8: Castilla | B8: 92.31 | C8: 100 | D8: 22 | E8: 7.32 | F8: 7.1 | G8: 84.85 | H8: 100 | I8: 20 | J8: 6.26 | K8: 6.26 | L8: 90.7 | M8: 100 | N8: 26 | O8: 6.54 | P8: 6.54 | Q8: 92.11 | R8: 100 | S8: 26 | T8: 6.61 | U8: 6.61 | V8: 94.74 | W8: 100 | X8: 26 | Y8: 6.95 | Z8: 6.79 | AB8: 92.31 | AC8: 26 | AD8: 6.9 | AE8: 6.17 | AG8: 92.86 | AH8: 42 | AI8: 6.61 | AJ8: 6.12 | AL8: 96.55 | AM8: 29 | AN8: 7.27 | AO8: 6.67 | AQ8: 88.89 | AR8: 27 | AS8: 7.58 | AT8: 6.54 | AV8: 96.15 | AW8: 26 | AX8: 7.39 | AY8: 6.59 | AZ8: 68.57 | BA8: 97.22 | BB8: 36 | BC8: 7.11 | BD8: 6.52
A9: IES Griñón | B9: 58.2 | C9: 92.31 | D9: 52 | E9: 6.83 | F9: 5.84 | G9: 66.67 | H9: 89.09 | I9: 55 | J9: 5.73 | K9: 5.49 | L9: 61.68 | M9: 92.86 | N9: 42 | O9: 6.12 | P9: 5.95 | Q9: 70 | R9: 89.58 | S9: 48 | T9: 5.87 | U9: 5.66 | V9: 66.67 | W9: 90.74 | X9: 54 | Y9: 6.81 | Z9: 6.05 | AA9: 77.59 | AB9: 86.08 | AC9: 79 | AD9: 6.98 | AE9: 5.8 | AF9: 91.67 | AG9: 78.69 | AH9: 61 | AI9: 7.18 | AJ9: 5.7 | AK9: 76.4 | AL9: 86.57 | AM9: 67 | AN9: 7.06 | AO9: 5.93 | AP9: 75.76 | AQ9: 85.71 | AR9: 42 | AS9: 6.96 | AT9: 5.74 | AU9: 84.29 | AV9: 90.74 | AW9: 54 | AX9: 7.34 | AY9: 6.25 | AZ9: 81.58 | BA9: 90 | BB9: 60 | BC9: 7.03 | BD9: 5.83
A10: Villa Griñón | B10: 81.25 | C10: 100 | D10: 13 | E10: 7.77 | F10: 7.81 | G10: 95 | H10: 100 | I10: 16 | J10: 7.98 | K10: 7.98 | L10: 96 | M10: 95.83 | N10: 24 | O10: 7.98 | P10: 7.84 | Q10: 100 | R10: 100 | S10: 24 | T10: 8.31 | U10: 8.31 | V10: 100 | W10: 100 | X10: 15 | Y10: 8.18 | Z10: 8.1 | AC10: 23 | AD10: 7.62 | AE10: 7.3 | AH10: 20 | AI10: 7.95 | AJ10: 7.96 | AM10: 31 | AN10: 8.48 | AO10: 8.12 | AR10: 24 | AS10: 7.87 | AT10: 7.81 | AW10: 25 | AX10: 8.19 | AY10: 8.21 | BB10: 36 | BC10: 7.73 | BD10: 7.61
A11: Catón | L11: 100 | M11: 100 | N11: 6 | O11: 5.92 | P11: 5.92 | Q11: 100 | R11: 100 | S11: 6 | T11: 6.01 | U11: 6.01 | V11: 91.67 | W11: 71.43 | X11: 7 | Y11: 6.75 | Z11: 6.2 | AB11: 76.92 | AC11: 13 | AD11: 6.98 | AE11: 5.45 | AG11: 94.12 | AH11: 17 | AI11: 6.81 | AJ11: 5.72 | AL11: 94.12 | AM11: 17 | AN11: 7.42 | AO11: 6.38 | AQ11: 85 | AR11: 20 | AS11: 7.64 | AT11: 6.41 | AV11: 84.62 | AW11: 13 | AX11: 7.77 | AY11: 6.77 | AZ11: 95.45 | BA11: 86.96 | BB11: 23 | BC11: 7.34 | BD11: 5.81
A12: IES Cubas | AK12: 70 | AL12: 92.59 | AM12: 27 | AN12: 7.26 | AO12: 6.25 | AP12: 82.46 | AQ12: 93.55 | AR12: 31 | AS12: 7.17 | AT12: 6.22 | AU12: 70.18 | AV12: 97.06 | AW12: 34 | AX12: 7.24 | AY12: 6.49 | AZ12: 88.89 | BA12: 95 | BB12: 40 | BC12: 7.27 | BD12: 6.68

Sheet Titulan
A1: ='Por año'!A117 -> 0 | B1: ='Por año'!B117 -> Materia | C1: ='Por año'!C117 -> Presentados
A2: 24-25 | B2: ='Por año'!B38 -> Titulan | C2: ='Por año'!C38 -> 52 | D2: =CONCATENATE(A2,"(",C2,")") -> 24-25(52) | E2: ='Por año'!E38 -> 0.7115
A3: 23-24 | B3: ='Por año'!B57 -> Titulan | C3: ='Por año'!C57 -> 60 | D3: =CONCATENATE(A3,"(",C3,")") -> 23-24(60) | E3: ='Por año'!E57 -> 0.7667
A4: 22-23 | B4: ='Por año'!B76 -> Titulan | C4: ='Por año'!C76 -> 54 | D4: =CONCATENATE(A4,"(",C4,")") -> 22-23(54) | E4: ='Por año'!E76 -> 0.7963
A5: ='Por año'!A94 -> 21-22 | B5: ='Por año'!B95 -> Titulan | C5: ='Por año'!C95 -> 59 | D5: =CONCATENATE(A5,"(",C5,")") -> 21-22(59) | E5: ='Por año'!E95 -> 0.8136
A6: ='Por año'!A113 -> 20-21 | B6: ='Por año'!B114 -> Titulan | C6: ='Por año'!C114 -> 54 | D6: =CONCATENATE(A6,"(",C6,")") -> 20-21(54) | E6: ='Por año'!E114 -> 0.907
A7: ='Por año'!A132 -> 19-20 | B7: ='Por año'!B133 -> Titulan | C7: ='Por año'!C133 -> 50 | D7: =CONCATENATE(A7,"(",C7,")") -> 19-20(50) | E7: ='Por año'!E133 -> 1
A8: ='Por año'!A151 -> 18-19 | B8: ='Por año'!B152 -> Titulan | C8: ='Por año'!C152 -> 54 | D8: =CONCATENATE(A8,"(",C8,")") -> 18-19(54) | E8: ='Por año'!E152 -> 0.6667
A9: ='Por año'!A170 -> 17-18 | B9: ='Por año'!B171 -> Titulan | C9: ='Por año'!C171 -> 44 | D9: =CONCATENATE(A9,"(",C9,")") -> 17-18(44) | E9: ='Por año'!E171 -> 0.7045
A10: ='Por año'!A189 -> 16-17 | B10: ='Por año'!B190 -> Titulan | C10: ='Por año'!C190 -> 45 | D10: =CONCATENATE(A10,"(",C10,")") -> 16-17(45) | E10: ='Por año'!E190 -> 0.7778
A17: ='Por año'!A194 -> 0 | B17: ='Por año'!B194 -> 0 | C17: ='Por año'!C194 -> 0 | E17: ='Por año'!F194 -> 0
A18: ='Por año'!A195 -> 0 | B18: ='Por año'!B195 -> 0 | C18: ='Por año'!C195 -> 0 | E18: ='Por año'!F195 -> 0
A19: ='Por año'!A196 -> 0 | B19: ='Por año'!B196 -> 0 | C19: ='Por año'!C196 -> 0 | E19: ='Por año'!F196 -> 0
A20: ='Por año'!A197 -> 0 | B20: ='Por año'!B197 -> 0 | C20: ='Por año'!C197 -> 0 | E20: ='Por año'!F197 -> 0
A21: ='Por año'!A198 -> 0 | B21: ='Por año'!B198 -> 0 | C21: ='Por año'!C198 -> 0 | E21: ='Por año'!F198 -> 0
A22: ='Por año'!A199 -> 0 | B22: ='Por año'!B199 -> 0 | C22: ='Por año'!C199 -> 0 | E22: ='Por año'!F199 -> 0
A23: ='Por año'!A200 -> 0 | B23: ='Por año'!B200 -> 0 | C23: ='Por año'!C200 -> 0 | E23: ='Por año'!F200 -> 0
A24: ='Por año'!A201 -> 0 | B24: ='Por año'!B201 -> 0 | C24: ='Por año'!C201 -> 0 | E24: ='Por año'!F201 -> 0
A25: ='Por año'!A202 -> 0 | B25: ='Por año'!B202 -> 0 | C25: ='Por año'!C202 -> 0 | E25: ='Por año'!F202 -> 0
A26: ='Por año'!A203 -> 0 | B26: ='Por año'!B203 -> 0 | C26: ='Por año'!C203 -> 0 | E26: ='Por año'!F203 -> 0
A27: ='Por año'!A204 -> 0 | B27: ='Por año'!B204 -> 0 | C27: ='Por año'!C204 -> 0 | E27: ='Por año'!F204 -> 0
A28: ='Por año'!A205 -> 0 | B28: ='Por año'!B205 -> 0 | C28: ='Por año'!C205 -> 0 | E28: ='Por año'!F205 -> 0
... A33: ='Por año'!A210 -> 0 | B33: ='Por año'!B210 -> 0 | C33: ='Por año'!C210 -> 0 | E33: ='Por año'!F210 -> 0

Sheet Fase General
A1: ='Por año'!A117 -> 0 | B1: ='Por año'!B117 -> Materia | C1: ='Por año'!C117 -> Presentados | E1: ='Por año'!E117 -> % LSG | F1: ='Por año'!F117 -> NM LSG EvAU | G1: ='Por año'!G117 -> NM LSG Cole | H1: ='Por año'!H117 -> % UC3M | I1: ='Por año'!I117 -> NM UC3M
A2: 25-26 | B2: Fase General | C2: 54 | D2: 25-26(54) | E2: 0.9153
A3: 24-25 | B3: ='Por año'!B37 -> Fase General | C3: ='Por año'!C37 -> 37 | D3: =CONCATENATE(A3,"(",C3,")") -> 24-25(37) | E3: ='Por año'!E37 -> 0.973 | F3: ='Por año'!F37 -> 6.01 | G3: ='Por año'!G37 -> 7.0656757 | I3: ='Por año'!I37 -> 6.437
A4: 23-24 | B4: ='Por año'!B56 -> Fase General | C4: ='Por año'!C56 -> 44 | D4: =CONCATENATE(A4,"(",C4,")") -> 23-24(44) | E4: ='Por año'!E56 -> 0.9318 | F4: ='Por año'!F56 -> 5.9 | G4: ='Por año'!G56 -> 6.8379096 | H4: ='Por año'!H56 -> 0.9572 | I4: ='Por año'!I56 -> 6.65
A5: 22-23 | B5: ='Por año'!B75 -> Fase General | C5: ='Por año'!C75 -> 43 | D5: =CONCATENATE(A5,"(",C5,")") -> 22-23(43) | E5: ='Por año'!E75 -> 0.9556 | F5: ='Por año'!F75 -> 6.41 | G5: ='Por año'!G75 -> 7.0848837 | H5: ='Por año'!H75 -> 0.9526 | I5: ='Por año'!I75 -> 6.743
A6: ='Por año'!A94 -> 21-22 | B6: ='Por año'!B94 -> Fase General | C6: ='Por año'!C94 -> 48 | D6: =CONCATENATE(A6,"(",C6,")") -> 21-22(48) | E6: ='Por año'!E94 -> 0.88 | F6: ='Por año'!F94 -> 6.1552083 | G6: ='Por año'!G94 -> 7.0147917 | H6: ='Por año'!H94 -> 0.9328 | I6: ='Por año'!I94 -> 6.49
A7: ='Por año'!A113 -> 20-21 | B7: ='Por año'!B113 -> Fase General | C7: ='Por año'!C113 -> 49 | D7: =CONCATENATE(A7,"(",C7,")") -> 20-21(49) | E7: ='Por año'!E113 -> 0.9592 | F7: ='Por año'!F113 -> 5.9013706 | G7: ='Por año'!G113 -> 6.6809137 | H7: ='Por año'!H113 -> 0.9368 | I7: ='Por año'!I113 -> 6.39
A8: ='Por año'!A132 -> 19-20 | B8: ='Por año'!B132 -> Fase General | C8: ='Por año'!C132 -> 50 | D8: =CONCATENATE(A8,"(",C8,")") -> 19-20(50) | E8: ='Por año'!E132 -> 0.88 | F8: ='Por año'!F132 -> 6.4415224 | G8: ='Por año'!G132 -> 8.0024876 | H8: ='Por año'!H132 -> 0.9024 | I8: ='Por año'!I132 -> 6.22
A9: ='Por año'!A151 -> 18-19 | B9: ='Por año'!B151 -> Fase General | C9: ='Por año'!C151 -> 36 | D9: =CONCATENATE(A9,"(",C9,")") -> 18-19(36) | E9: ='Por año'!E151 -> 0.9444 | F9: ='Por año'!F151 -> 6.0688828 | G9: ='Por año'!G151 -> 6.708 | H9: ='Por año'!H151 -> 0.9086 | I9: ='Por año'!I151 -> 6.03
A10: ='Por año'!A170 -> 17-18 | B10: ='Por año'!B170 -> Fase General | C10: ='Por año'!C170 -> 31 | D10: =CONCATENATE(A10,"(",C10,")") -> 17-18(31) | E10: ='Por año'!E170 -> 0.9355 | F10: ='Por año'!F170 -> 5.8432698 | G10: ='Por año'!G170 -> 6.6826984 | H10: ='Por año'!H170 -> 0.9226 | I10: ='Por año'!I170 -> 6.11
A11: ='Por año'!A189 -> 16-17 | B11: ='Por año'!B189 -> Fase General | C11: ='Por año'!C189 -> 35 | D11: =CONCATENATE(A11,"(",C11,")") -> 16-17(35) | E11: ='Por año'!E189 -> 0.9429 | F11: ='Por año'!F189 -> 6.0051915 | G11: ='Por año'!G189 -> 6.779078 | H11: ='Por año'!H189 -> 0.8896 | I11: ='Por año'!I189 -> 5.97
I17: ='Por año'!K174 -> 0
A18: ='Por año'!A194 -> 0 | B18: ='Por año'!B194 -> 0 | C18: ='Por año'!C194 -> 0 | F18: ='Por año'!F194 -> 0 | I18: ='Por año'!K175 -> 0
A19: ='Por año'!A195 -> 0 | B19: ='Por año'!B195 -> 0 | C19: ='Por año'!C195 -> 0 | F19: ='Por año'!F195 -> 0 | I19: ='Por año'!K176 -> 0
A20: ='Por año'!A196 -> 0 | B20: ='Por año'!B196 -> 0 | C20: ='Por año'!C196 -> 0 | F20: ='Por año'!F196 -> 0 | I20: ='Por año'!K177 -> 0
A21: ='Por año'!A197 -> 0 | B21: ='Por año'!B197 -> 0 | C21: ='Por año'!C197 -> 0 | F21: ='Por año'!F197 -> 0 | I21: ='Por año'!K178 -> 0
A22: ='Por año'!A198 -> 0 | B22: ='Por año'!B198 -> 0 | C22: ='Por año'!C198 -> 0 | F22: ='Por año'!F198 -> 0 | I22: ='Por año'!K179 -> 0
A23: ='Por año'!A199 -> 0 | B23: ='Por año'!B199 -> 0 | C23: ='Por año'!C199 -> 0 | F23: ='Por año'!F199 -> 0 | I23: ='Por año'!K180 -> 0
A24: ='Por año'!A200 -> 0 | B24: ='Por año'!B200 -> 0 | C24: ='Por año'!C200 -> 0 | F24: ='Por año'!F200 -> 0 | I24: ='Por año'!K181 -> 0
A25: ='Por año'!A201 -> 0 | B25: ='Por año'!B201 -> 0 | C25: ='Por año'!C201 -> 0 | F25: ='Por año'!F201 -> 0 | I25: ='Por año'!K182 -> 0
A26: ='Por año'!A202 -> 0 | B26: ='Por año'!B202 -> 0 | C26: ='Por año'!C202 -> 0 | F26: ='Por año'!F202 -> 0 | I26: ='Por año'!K183 -> 0
A27: ='Por año'!A203 -> 0 | B27: ='Por año'!B203 -> 0 | C27: ='Por año'!C203 -> 0 | F27: ='Por año'!F203 -> 0 | I27: ='Por año'!K184 -> 0
A28: ='Por año'!A204 -> 0 | B28: ='Por año'!B204 -> 0 | C28: ='Por año'!C204 -> 0 | F28: ='Por año'!F204 -> 0 | I28: ='Por año'!K185 -> 0
A29: ='Por año'!A205 -> 0 | B29: ='Por año'!B205 -> 0 | C29: ='Por año'!C205 -> 0 | F29: ='Por año'!F205 -> 0 | I29: ='Por año'!K186 -> 0
... A34: ='Por año'!A210 -> 0 | B34: ='Por año'!B210 -> 0 | C34: ='Por año'!C210 -> 0 | F34: ='Por año'!F210 -> 0 | I34: ='Por año'!K191 -> 0

Sheet Lengua
A1: ='Por año'!A117 -> 0 | B1: ='Por año'!B117 -> Materia | C1: ='Por año'!C117 -> Presentados | E1: ='Por año'!E117 -> % LSG | F1: NM LSG EvAU | G1: NM LSG Cole | H1: ='Por año'!H117 -> % UC3M | I1: ='Por año'!I117 -> NM UC3M | J1: ='Por año'!K98 -> 0
A2: ='Por año'!A23 -> 24-25 | B2: ='Por año'!B23 -> Lengua | C2: ='Por año'!C23 -> 37 | D2: =CONCATENATE(A2,"(",C2,")") -> 24-25(37) | E2: ='Por año'!E23 -> 0.7027 | F2: ='Por año'!F23 -> 5.37 | G2: ='Por año'!G23 -> 7.16 | H2: ='Por año'!H23 -> 0.8326 | I2: ='Por año'!I23 -> 6.5
A3: ='Por año'!A42 -> 23-24 | B3: ='Por año'!B42 -> Lengua | C3: ='Por año'!C42 -> 44 | D3: =CONCATENATE(A3,"(",C3,")") -> 23-24(44) | E3: ='Por año'!E42 -> 0.7333 | F3: ='Por año'!F42 -> 5.66 | G3: ='Por año'!G42 -> 6.73 | H3: ='Por año'!H42 -> 0.8821 | I3: ='Por año'!I42 -> 6.86
A4: ='Por año'!A61 -> 22-23 | B4: ='Por año'!B61 -> Lengua | C4: ='Por año'!C61 -> 43 | D4: =CONCATENATE(A4,"(",C4,")") -> 22-23(43) | E4: ='Por año'!E61 -> 0.7111 | F4: ='Por año'!F61 -> 5.68 | G4: ='Por año'!G61 -> 7.2 | H4: ='Por año'!H61 -> 0.8378 | I4: ='Por año'!I61 -> 6.61
A5: ='Por año'!A80 -> 21-22 | B5: ='Por año'!B80 -> Lengua | C5: ='Por año'!C80 -> 48 | D5: =CONCATENATE(A5,"(",C5,")") -> 21-22(48) | E5: ='Por año'!E80 -> 0.6735 | F5: ='Por año'!F80 -> 6.19 | G5: ='Por año'!G80 -> 6.77 | H5: ='Por año'!H80 -> 0.8373 | I5: ='Por año'!I80 -> 6.66
A6: ='Por año'!A99 -> 20-21 | B6: ='Por año'!B99 -> Lengua | C6: ='Por año'!C99 -> 49 | D6: =CONCATENATE(A6,"(",C6,")") -> 20-21(49) | E6: ='Por año'!E99 -> 0.7083 | F6: ='Por año'!F99 -> 5.82 | G6: ='Por año'!G99 -> 6.43 | H6: ='Por año'!H99 -> 0.8332 | I6: ='Por año'!I99 -> 6.54
A7: ='Por año'!A118 -> 19-20 | B7: ='Por año'!B118 -> Lengua | C7: ='Por año'!C118 -> 50 | D7: =CONCATENATE(A7,"(",C7,")") -> 19-20(50) | E7: ='Por año'!E118 -> 0.62 | F7: ='Por año'!F118 -> 6.155 | G7: ='Por año'!G118 -> 7.96 | H7: ='Por año'!H118 -> 0.786 | I7: ='Por año'!I118 -> 6.366
A8: ='Por año'!A137 -> 18-19 | B8: ='Por año'!B137 -> Lengua | C8: ='Por año'!C137 -> 36 | D8: =CONCATENATE(A8,"(",C8,")") -> 18-19(36) | E8: ='Por año'!E137 -> 0.6944 | F8: ='Por año'!F137 -> 5.646 | G8: ='Por año'!G137 -> 6.53 | H8: ='Por año'!H137 -> 0.803 | I8: ='Por año'!I137 -> 6.434
A9: ='Por año'!A156 -> 17-18 | B9: ='Por año'!B156 -> Lengua | C9: ='Por año'!C156 -> 31 | D9: =CONCATENATE(A9,"(",C9,")") -> 17-18(31) | E9: ='Por año'!E156 -> 0.5806 | F9: ='Por año'!F156 -> 4.944 | G9: ='Por año'!G156 -> 6.46 | H9: ='Por año'!H156 -> 0.7434 | I9: ='Por año'!I156 -> 5.955
A10: ='Por año'!A175 -> 16-17 | B10: ='Por año'!B175 -> Lengua | C10: ='Por año'!C175 -> 35 | D10: =CONCATENATE(A10,"(",C10,")") -> 16-17(35) | E10: ='Por año'!E175 -> 0.6 | F10: ='Por año'!F175 -> 5.5 | G10: ='Por año'!G175 -> 6.43 | H10: ='Por año'!H175 -> 0.7856 | I10: ='Por año'!I175 -> 6.165
J11: ='Por año'!K170 -> 0
A12: ='Por año'!A191 -> 0 | B12: ='Por año'!B191 -> 0 | C12: ='Por año'!C191 -> 0 | E12: ='Por año'!E191 -> 0 | F12: ='Por año'!F191 -> 0 | H12: ='Por año'!H191 -> 0 | I12: ='Por año'!I191 -> 0 | J12: ='Por año'!K172 -> 0
A13: ='Por año'!A192 -> 0 | B13: ='Por año'!B192 -> 0 | C13: ='Por año'!C192 -> 0 | E13: ='Por año'!E192 -> 0 | F13: ='Por año'!F192 -> 0 | H13: ='Por año'!H192 -> 0 | I13: ='Por año'!I192 -> 0 | J13: ='Por año'!K173 -> 0
A14: ='Por año'!A193 -> 0 | B14: ='Por año'!B193 -> 0 | C14: ='Por año'!C193 -> 0 | E14: ='Por año'!E193 -> 0 | F14: ='Por año'!F193 -> 0 | H14: ='Por año'!H193 -> 0 | I14: ='Por año'!I193 -> 0 | J14: ='Por año'!K174 -> 0
A15: ='Por año'!A194 -> 0 | B15: ='Por año'!B194 -> 0 | C15: ='Por año'!C194 -> 0 | E15: ='Por año'!E194 -> 0 | F15: ='Por año'!F194 -> 0 | H15: ='Por año'!H194 -> 0 | I15: ='Por año'!I194 -> 0 | J15: ='Por año'!K175 -> 0
A16: ='Por año'!A195 -> 0 | B16: ='Por año'!B195 -> 0 | C16: ='Por año'!C195 -> 0 | E16: ='Por año'!E195 -> 0 | F16: ='Por año'!F195 -> 0 | H16: ='Por año'!H195 -> 0 | I16: ='Por año'!I195 -> 0 | J16: ='Por año'!K176 -> 0
A17: ='Por año'!A196 -> 0 | B17: ='Por año'!B196 -> 0 | C17: ='Por año'!C196 -> 0 | E17: ='Por año'!E196 -> 0 | F17: ='Por año'!F196 -> 0 | H17: ='Por año'!H196 -> 0 | I17: ='Por año'!I196 -> 0 | J17: ='Por año'!K177 -> 0
A18: ='Por año'!A197 -> 0 | B18: ='Por año'!B197 -> 0 | C18: ='Por año'!C197 -> 0 | E18: ='Por año'!E197 -> 0 | F18: ='Por año'!F197 -> 0 | H18: ='Por año'!H197 -> 0 | I18: ='Por año'!I197 -> 0 | J18: ='Por año'!K178 -> 0
A19: ='Por año'!A198 -> 0 | B19: ='Por año'!B198 -> 0 | C19: ='Por año'!C198 -> 0 | E19: ='Por año'!E198 -> 0 | F19: ='Por año'!F198 -> 0 | H19: ='Por año'!H198 -> 0 | I19: ='Por año'!I198 -> 0 | J19: ='Por año'!K179 -> 0
A20: ='Por año'!A199 -> 0 | B20: ='Por año'!B199 -> 0 | C20: ='Por año'!C199 -> 0 | E20: ='Por año'!E199 -> 0 | F20: ='Por año'!F199 -> 0 | H20: ='Por año'!H199 -> 0 | I20: ='Por año'!I199 -> 0 | J20: ='Por año'!K180 -> 0
A21: ='Por año'!A200 -> 0 | B21: ='Por año'!B200 -> 0 | C21: ='Por año'!C200 -> 0 | E21: ='Por año'!E200 -> 0 | F21: ='Por año'!F200 -> 0 | H21: ='Por año'!H200 -> 0 | I21: ='Por año'!I200 -> 0 | J21: ='Por año'!K181 -> 0
A22: ='Por año'!A201 -> 0 | B22: ='Por año'!B201 -> 0 | C22: ='Por año'!C201 -> 0 | E22: ='Por año'!E201 -> 0 | F22: ='Por año'!F201 -> 0 | H22: ='Por año'!H201 -> 0 | I22: ='Por año'!I201 -> 0 | J22: ='Por año'!K182 -> 0
A23: ='Por año'!A202 -> 0 | B23: ='Por año'!B202 -> 0 | C23: ='Por año'!C202 -> 0 | E23: ='Por año'!E202 -> 0 | F23: ='Por año'!F202 -> 0 | H23: ='Por año'!H202 -> 0 | I23: ='Por año'!I202 -> 0 | J23: ='Por año'!K183 -> 0
... A31: ='Por año'!A210 -> 0 | B31: ='Por año'!B210 -> 0 | C31: ='Por año'!C210 -> 0 | E31: ='Por año'!E210 -> 0 | F31: ='Por año'!F210 -> 0 | H31: ='Por año'!H210 -> 0 | I31: ='Por año'!I210 -> 0 | J31: ='Por año'!K191 -> 0

Sheet Inglés
A1: ='Por año'!A117 -> 0 | B1: ='Por año'!B117 -> Materia | C1: ='Por año'!C117 -> Presentados | E1: ='Por año'!E117 -> % LSG | F1: ='Por año'!F117 -> NM LSG EvAU | G1: ='Por año'!G117 -> NM LSG Cole | H1: ='Por año'!H117 -> % UC3M | I1: ='Por año'!I117 -> NM UC3M | J1: ='Por año'!K98 -> 0
A2: ='Por año'!A24 -> 24-25 | B2: ='Por año'!B24 -> Inglés | C2: ='Por año'!C24 -> 37 | D2: =CONCATENATE(A2,"(",C2,")") -> 24-25(37) | E2: ='Por año'!E24 -> 0.8378 | F2: ='Por año'!F24 -> 7.01 | G2: ='Por año'!G24 -> 7 | H2: ='Por año'!H24 -> 0.8447 | I2: ='Por año'!I24 -> 7.15
A3: ='Por año'!A43 -> 23-24 | B3: ='Por año'!B43 -> Inglés | C3: ='Por año'!C43 -> 44 | D3: =CONCATENATE(A3,"(",C3,")") -> 23-24(44) | E3: ='Por año'!E43 -> 0.6444 | F3: ='Por año'!F43 -> 5.85 | G3: ='Por año'!G43 -> 7 | H3: ='Por año'!H43 -> 0.8231 | I3: ='Por año'!I43 -> 6.84
A4: ='Por año'!A62 -> 22-23 | B4: ='Por año'!B62 -> Inglés | C4: ='Por año'!C62 -> 43 | D4: =CONCATENATE(A4,"(",C4,")") -> 22-23(43) | E4: ='Por año'!E62 -> 0.7556 | F4: ='Por año'!F62 -> 6.55 | G4: ='Por año'!G62 -> 6.84 | H4: ='Por año'!H62 -> 0.8713 | I4: ='Por año'!I62 -> 7.28
A5: ='Por año'!A81 -> 21-22 | B5: ='Por año'!B81 -> Inglés | C5: ='Por año'!C81 -> 48 | D5: =CONCATENATE(A5,"(",C5,")") -> 21-22(48) | E5: ='Por año'!E81 -> 0.5918 | F5: ='Por año'!F81 -> 5.6 | G5: ='Por año'!G81 -> 7 | H5: ='Por año'!H81 -> 0.7533 | I5: ='Por año'!I81 -> 6.35
A6: ='Por año'!A100 -> 20-21 | B6: ='Por año'!B100 -> Inglés | C6: ='Por año'!C100 -> 49 | D6: =CONCATENATE(A6,"(",C6,")") -> 20-21(49) | E6: ='Por año'!E100 -> 0.5918 | F6: ='Por año'!F100 -> 5.28 | G6: ='Por año'!G100 -> 6.51 | H6: ='Por año'!H100 -> 0.7798 | I6: ='Por año'!I100 -> 6.48
A7: ='Por año'!A119 -> 19-20 | B7: ='Por año'!B119 -> Inglés | C7: ='Por año'!C119 -> 50 | D7: =CONCATENATE(A7,"(",C7,")") -> 19-20(50) | E7: ='Por año'!E119 -> 0.8 | F7: ='Por año'!F119 -> 6.86 | G7: ='Por año'!G119 -> 8.08 | H7: ='Por año'!H119 -> 0.7849 | I7: ='Por año'!I119 -> 6.701
A8: ='Por año'!A138 -> 18-19 | B8: ='Por año'!B138 -> Inglés | C8: ='Por año'!C138 -> 36 | D8: =CONCATENATE(A8,"(",C8,")") -> 18-19(36) | E8: ='Por año'!E138 -> 0.8056 | F8: ='Por año'!F138 -> 6.472 | G8: ='Por año'!G138 -> 6.6 | H8: ='Por año'!H138 -> 0.8045 | I8: ='Por año'!I138 -> 6.782
A9: ='Por año'!A157 -> 17-18 | B9: ='Por año'!B157 -> Inglés | C9: ='Por año'!C157 -> 31 | D9: =CONCATENATE(A9,"(",C9,")") -> 17-18(31) | E9: ='Por año'!E157 -> 0.7419 | F9: ='Por año'!F157 -> 6.661 | G9: ='Por año'!G157 -> 6.62 | H9: ='Por año'!H157 -> 0.779 | I9: ='Por año'!I157 -> 6.57
A10: ='Por año'!A176 -> 16-17 | B10: ='Por año'!B176 -> Inglés | C10: ='Por año'!C176 -> 35 | D10: =CONCATENATE(A10,"(",C10,")") -> 16-17(35) | E10: ='Por año'!E176 -> 0.8286 | F10: ='Por año'!F176 -> 6.043 | G10: ='Por año'!G176 -> 6.73 | H10: ='Por año'!H176 -> 0.7648 | I10: ='Por año'!I176 -> 6.521
I11: ='Por año'!I189 -> 5.97 | J11: ='Por año'!K170 -> 0
A12: ='Por año'!A191 -> 0 | B12: ='Por año'!B191 -> 0 | C12: ='Por año'!C191 -> 0 | E12: ='Por año'!E191 -> 0 | F12: ='Por año'!F191 -> 0 | H12: ='Por año'!H191 -> 0 | I12: ='Por año'!I191 -> 0 | J12: ='Por año'!K172 -> 0
A13: ='Por año'!A192 -> 0 | B13: ='Por año'!B192 -> 0 | C13: ='Por año'!C192 -> 0 | E13: ='Por año'!E192 -> 0 | F13: ='Por año'!F192 -> 0 | H13: ='Por año'!H192 -> 0 | I13: ='Por año'!I192 -> 0 | J13: ='Por año'!K173 -> 0
A14: ='Por año'!A193 -> 0 | B14: ='Por año'!B193 -> 0 | C14: ='Por año'!C193 -> 0 | E14: ='Por año'!E193 -> 0 | F14: ='Por año'!F193 -> 0 | H14: ='Por año'!H193 -> 0 | I14: ='Por año'!I193 -> 0 | J14: ='Por año'!K174 -> 0
A15: ='Por año'!A194 -> 0 | B15: ='Por año'!B194 -> 0 | C15: ='Por año'!C194 -> 0 | E15: ='Por año'!E194 -> 0 | F15: ='Por año'!F194 -> 0 | H15: ='Por año'!H194 -> 0 | I15: ='Por año'!I194 -> 0 | J15: ='Por año'!K175 -> 0
A16: ='Por año'!A195 -> 0 | B16: ='Por año'!B195 -> 0 | C16: ='Por año'!C195 -> 0 | E16: ='Por año'!E195 -> 0 | F16: ='Por año'!F195 -> 0 | H16: ='Por año'!H195 -> 0 | I16: ='Por año'!I195 -> 0 | J16: ='Por año'!K176 -> 0
A17: ='Por año'!A196 -> 0 | B17: ='Por año'!B196 -> 0 | C17: ='Por año'!C196 -> 0 | E17: ='Por año'!E196 -> 0 | F17: ='Por año'!F196 -> 0 | H17: ='Por año'!H196 -> 0 | I17: ='Por año'!I196 -> 0 | J17: ='Por año'!K177 -> 0
A18: ='Por año'!A197 -> 0 | B18: ='Por año'!B197 -> 0 | C18: ='Por año'!C197 -> 0 | E18: ='Por año'!E197 -> 0 | F18: ='Por año'!F197 -> 0 | H18: ='Por año'!H197 -> 0 | I18: ='Por año'!I197 -> 0 | J18: ='Por año'!K178 -> 0
A19: ='Por año'!A198 -> 0 | B19: ='Por año'!B198 -> 0 | C19: ='Por año'!C198 -> 0 | E19: ='Por año'!E198 -> 0 | F19: ='Por año'!F198 -> 0 | H19: ='Por año'!H198 -> 0 | I19: ='Por año'!I198 -> 0 | J19: ='Por año'!K179 -> 0
A20: ='Por año'!A199 -> 0 | B20: ='Por año'!B199 -> 0 | C20: ='Por año'!C199 -> 0 | E20: ='Por año'!E199 -> 0 | F20: ='Por año'!F199 -> 0 | H20: ='Por año'!H199 -> 0 | I20: ='Por año'!I199 -> 0 | J20: ='Por año'!K180 -> 0
A21: ='Por año'!A200 -> 0 | B21: ='Por año'!B200 -> 0 | C21: ='Por año'!C200 -> 0 | E21: ='Por año'!E200 -> 0 | F21: ='Por año'!F200 -> 0 | H21: ='Por año'!H200 -> 0 | I21: ='Por año'!I200 -> 0 | J21: ='Por año'!K181 -> 0
A22: ='Por año'!A201 -> 0 | B22: ='Por año'!B201 -> 0 | C22: ='Por año'!C201 -> 0 | E22: ='Por año'!E201 -> 0 | F22: ='Por año'!F201 -> 0 | H22: ='Por año'!H201 -> 0 | I22: ='Por año'!I201 -> 0 | J22: ='Por año'!K182 -> 0
A23: ='Por año'!A202 -> 0 | B23: ='Por año'!B202 -> 0 | C23: ='Por año'!C202 -> 0 | E23: ='Por año'!E202 -> 0 | F23: ='Por año'!F202 -> 0 | H23: ='Por año'!H202 -> 0 | I23: ='Por año'!I202 -> 0 | J23: ='Por año'!K183 -> 0
... A31: ='Por año'!A210 -> 0 | B31: ='Por año'!B210 -> 0 | C31: ='Por año'!C210 -> 0 | E31: ='Por año'!E210 -> 0 | F31: ='Por año'!F210 -> 0 | H31: ='Por año'!H210 -> 0 | I31: ='Por año'!I210 -> 0 | J31: ='Por año'!K191 -> 0

Sheet Historia
A1: ='Por año'!A117 -> 0 | B1: ='Por año'!B117 -> Materia | C1: ='Por año'!C117 -> Presentados | E1: ='Por año'!E117 -> % LSG | F1: ='Por año'!F117 -> NM LSG EvAU | G1: ='Por año'!G117 -> NM LSG Cole | H1: ='Por año'!H117 -> % UC3M | I1: ='Por año'!I117 -> NM UC3M | J1: ='Por año'!K98 -> 0
A2: ='Por año'!A25 -> 24-25 | B2: ='Por año'!B25 -> Historia | C2: ='Por año'!C25 -> 9 | D2: =CONCATENATE(A2,"(",C2,")") -> 24-25(9) | E2: ='Por año'!E25 -> 0.6667 | F2: ='Por año'!F25 -> 5.89 | G2: ='Por año'!G25 -> 6.59 | H2: ='Por año'!H25 -> 0.8244 | I2: ='Por año'!I25 -> 6.91
A3: ='Por año'!A44 -> 23-24 | B3: ='Por año'!B44 -> Historia | C3: ='Por año'!C44 -> 18 | D3: =CONCATENATE(A3,"(",C3,")") -> 23-24(18) | E3: ='Por año'!E44 -> 0.5789 | F3: ='Por año'!F44 -> 5.55 | G3: ='Por año'!G44 -> 6.92 | H3: ='Por año'!H44 -> 0.7864 | I3: ='Por año'!I44 -> 6.68
A4: ='Por año'!A63 -> 22-23 | B4: ='Por año'!B63 -> Historia | C4: ='Por año'!C63 -> 43 | D4: =CONCATENATE(A4,"(",C4,")") -> 22-23(43) | E4: ='Por año'!E63 -> 0.7111 | F4: ='Por año'!F63 -> 6.31 | G4: ='Por año'!G63 -> 7.3 | H4: ='Por año'!H63 -> 0.7989 | I4: ='Por año'!I63 -> 6.73
A5: ='Por año'!A82 -> 21-22 | B5: ='Por año'!B82 -> Historia | C5: ='Por año'!C82 -> 48 | D5: =CONCATENATE(A5,"(",C5,")") -> 21-22(48) | E5: ='Por año'!E82 -> 0.6531 | F5: ='Por año'!F82 -> 5.89 | G5: ='Por año'!G82 -> 7.3 | H5: ='Por año'!H82 -> 0.7466 | I5: ='Por año'!I82 -> 6.49
A6: ='Por año'!A101 -> 20-21 | B6: ='Por año'!B101 -> Historia | C6: ='Por año'!C101 -> 49 | D6: =CONCATENATE(A6,"(",C6,")") -> 20-21(49) | E6: ='Por año'!E101 -> 0.6735 | F6: ='Por año'!F101 -> 5.97 | G6: ='Por año'!G101 -> 6.94 | H6: ='Por año'!H101 -> 0.7692 | I6: ='Por año'!I101 -> 6.61
A7: ='Por año'!A120 -> 19-20 | B7: ='Por año'!B120 -> Historia | C7: ='Por año'!C120 -> 50 | D7: =CONCATENATE(A7,"(",C7,")") -> 19-20(50) | E7: ='Por año'!E120 -> 0.6 | F7: ='Por año'!F120 -> 5.64 | G7: ='Por año'!G120 -> 8.33 | H7: ='Por año'!H120 -> 0.6981 | I7: ='Por año'!I120 -> 6.089
A8: ='Por año'!A139 -> 18-19 | B8: ='Por año'!B139 -> Historia | C8: ='Por año'!C139 -> 36 | D8: =CONCATENATE(A8,"(",C8,")") -> 18-19(36) | E8: ='Por año'!E139 -> 0.5833 | F8: ='Por año'!F139 -> 5.819 | G8: ='Por año'!G139 -> 7.07 | H8: ='Por año'!H139 -> 0.6415 | I8: ='Por año'!I139 -> 5.752
A9: ='Por año'!A158 -> 17-18 | B9: ='Por año'!B158 -> Historia | C9: ='Por año'!C158 -> 31 | D9: =CONCATENATE(A9,"(",C9,")") -> 17-18(31) | E9: ='Por año'!E158 -> 0.7097 | F9: ='Por año'!F158 -> 5.661 | G9: ='Por año'!G158 -> 7.15 | H9: ='Por año'!H158 -> 0.6754 | I9: ='Por año'!I158 -> 5.88
A10: ='Por año'!A177 -> 16-17 | B10: ='Por año'!B177 -> Historia | C10: ='Por año'!C177 -> 35 | D10: =CONCATENATE(A10,"(",C10,")") -> 16-17(35) | E10: ='Por año'!E177 -> 0.6571 | F10: ='Por año'!F177 -> 5.421 | G10: ='Por año'!G177 -> 6.95 | H10: ='Por año'!H177 -> 0.6388 | I10: ='Por año'!I177 -> 5.642
H11: ='Por año'!H189 -> 0.8896 | I11: ='Por año'!I189 -> 5.97 | J11: ='Por año'!K170 -> 0
A12: ='Por año'!A191 -> 0 | B12: ='Por año'!B191 -> 0 | C12: ='Por año'!C191 -> 0 | E12: ='Por año'!E191 -> 0 | F12: ='Por año'!F191 -> 0 | H12: ='Por año'!H191 -> 0 | I12: ='Por año'!I191 -> 0 | J12: ='Por año'!K172 -> 0
A13: ='Por año'!A192 -> 0 | B13: ='Por año'!B192 -> 0 | C13: ='Por año'!C192 -> 0 | E13: ='Por año'!E192 -> 0 | F13: ='Por año'!F192 -> 0 | H13: ='Por año'!H192 -> 0 | I13: ='Por año'!I192 -> 0 | J13: ='Por año'!K173 -> 0
A14: ='Por año'!A193 -> 0 | B14: ='Por año'!B193 -> 0 | C14: ='Por año'!C193 -> 0 | E14: ='Por año'!E193 -> 0 | F14: ='Por año'!F193 -> 0 | H14: ='Por año'!H193 -> 0 | I14: ='Por año'!I193 -> 0 | J14: ='Por año'!K174 -> 0
A15: ='Por año'!A194 -> 0 | B15: ='Por año'!B194 -> 0 | C15: ='Por año'!C194 -> 0 | E15: ='Por año'!E194 -> 0 | F15: ='Por año'!F194 -> 0 | H15: ='Por año'!H194 -> 0 | I15: ='Por año'!I194 -> 0 | J15: ='Por año'!K175 -> 0
A16: ='Por año'!A195 -> 0 | B16: ='Por año'!B195 -> 0 | C16: ='Por año'!C195 -> 0 | E16: ='Por año'!E195 -> 0 | F16: ='Por año'!F195 -> 0 | H16: ='Por año'!H195 -> 0 | I16: ='Por año'!I195 -> 0 | J16: ='Por año'!K176 -> 0
A17: ='Por año'!A196 -> 0 | B17: ='Por año'!B196 -> 0 | C17: ='Por año'!C196 -> 0 | E17: ='Por año'!E196 -> 0 | F17: ='Por año'!F196 -> 0 | H17: ='Por año'!H196 -> 0 | I17: ='Por año'!I196 -> 0 | J17: ='Por año'!K177 -> 0
A18: ='Por año'!A197 -> 0 | B18: ='Por año'!B197 -> 0 | C18: ='Por año'!C197 -> 0 | E18: ='Por año'!E197 -> 0 | F18: ='Por año'!F197 -> 0 | H18: ='Por año'!H197 -> 0 | I18: ='Por año'!I197 -> 0 | J18: ='Por año'!K178 -> 0
A19: ='Por año'!A198 -> 0 | B19: ='Por año'!B198 -> 0 | C19: ='Por año'!C198 -> 0 | E19: ='Por año'!E198 -> 0 | F19: ='Por año'!F198 -> 0 | H19: ='Por año'!H198 -> 0 | I19: ='Por año'!I198 -> 0 | J19: ='Por año'!K179 -> 0
A20: ='Por año'!A199 -> 0 | B20: ='Por año'!B199 -> 0 | C20: ='Por año'!C199 -> 0 | E20: ='Por año'!E199 -> 0 | F20: ='Por año'!F199 -> 0 | H20: ='Por año'!H199 -> 0 | I20: ='Por año'!I199 -> 0 | J20: ='Por año'!K180 -> 0
A21: ='Por año'!A200 -> 0 | B21: ='Por año'!B200 -> 0 | C21: ='Por año'!C200 -> 0 | E21: ='Por año'!E200 -> 0 | F21: ='Por año'!F200 -> 0 | H21: ='Por año'!H200 -> 0 | I21: ='Por año'!I200 -> 0 | J21: ='Por año'!K181 -> 0
A22: ='Por año'!A201 -> 0 | B22: ='Por año'!B201 -> 0 | C22: ='Por año'!C201 -> 0 | E22: ='Por año'!E201 -> 0 | F22: ='Por año'!F201 -> 0 | H22: ='Por año'!H201 -> 0 | I22: ='Por año'!I201 -> 0 | J22: ='Por año'!K182 -> 0
A23: ='Por año'!A202 -> 0 | B23: ='Por año'!B202 -> 0 | C23: ='Por año'!C202 -> 0 | E23: ='Por año'!E202 -> 0 | F23: ='Por año'!F202 -> 0 | H23: ='Por año'!H202 -> 0 | I23: ='Por año'!I202 -> 0 | J23: ='Por año'!K183 -> 0
... A31: ='Por año'!A210 -> 0 | B31: ='Por año'!B210 -> 0 | C31: ='Por año'!C210 -> 0 | E31: ='Por año'!E210 -> 0 | F31: ='Por año'!F210 -> 0 | H31: ='Por año'!H210 -> 0 | I31: ='Por año'!I210 -> 0 | J31: ='Por año'!K191 -> 0

Sheet Mate II
A1: ='Por año'!A117 -> 0 | B1: ='Por año'!B117 -> Materia | C1: ='Por año'!C117 -> Presentados | E1: ='Por año'!E117 -> % LSG | F1: ='Por año'!F117 -> NM LSG EvAU | G1: ='Por año'!G117 -> NM LSG Cole | H1: ='Por año'!H117 -> % UC3M | I1: ='Por año'!I117 -> NM UC3M | J1: ='Por año'!K98 -> 0
A2: ='Por año'!A26 -> 24-25 | B2: ='Por año'!B26 -> Mate | C2: ='Por año'!C26 -> 30 | D2: =CONCATENATE(A2,"(",C2,")") -> 24-25(30) | E2: ='Por año'!E26 -> 0.6333 | F2: ='Por año'!F26 -> 5.19 | G2: ='Por año'!G26 -> 7 | H2: ='Por año'!H26 -> 0.5941 | I2: ='Por año'!I26 -> 5.47
A3: ='Por año'!A45 -> 23-24 | B3: ='Por año'!B45 -> Mate | C3: ='Por año'!C45 -> 35 | D3: =CONCATENATE(A3,"(",C3,")") -> 23-24(35) | E3: ='Por año'!E45 -> 0.6944 | F3: ='Por año'!F45 -> 5.87 | G3: ='Por año'!G45 -> 6.62 | H3: ='Por año'!H45 -> 0.6822 | I3: ='Por año'!I45 -> 5.8
A4: ='Por año'!A64 -> 22-23 | B4: ='Por año'!B64 -> Mate | C4: ='Por año'!C64 -> 25 | D4: =CONCATENATE(A4,"(",C4,")") -> 22-23(25) | E4: ='Por año'!E64 -> 0.8519 | F4: ='Por año'!F64 -> 6.78 | G4: ='Por año'!G64 -> 6.92 | H4: ='Por año'!H64 -> 0.7599 | I4: ='Por año'!I64 -> 6.48
A5: ='Por año'!A83 -> 21-22 | B5: ='Por año'!B83 -> Mate | C5: ='Por año'!C83 -> 28 | D5: =CONCATENATE(A5,"(",C5,")") -> 21-22(28) | E5: ='Por año'!E83 -> 0.8966 | F5: ='Por año'!F83 -> 7.47 | G5: ='Por año'!G83 -> 7.21 | H5: ='Por año'!H83 -> 0.8134 | I5: ='Por año'!I83 -> 6.74
A6: ='Por año'!A102 -> 20-21 | B6: ='Por año'!B102 -> Mate | C6: ='Por año'!C102 -> 31 | D6: =CONCATENATE(A6,"(",C6,")") -> 20-21(31) | E6: ='Por año'!E102 -> 0.8065 | F6: ='Por año'!F102 -> 6.31 | G6: ='Por año'!G102 -> 6.81 | H6: ='Por año'!H102 -> 0.7154 | I6: ='Por año'!I102 -> 6.15
A7: ='Por año'!A121 -> 19-20 | B7: ='Por año'!B121 -> Mate | C7: ='Por año'!C121 -> 31 | D7: =CONCATENATE(A7,"(",C7,")") -> 19-20(31) | E7: ='Por año'!E121 -> 0.8387 | F7: ='Por año'!F121 -> 7.556 | G7: ='Por año'!G121 -> 7.6 | H7: ='Por año'!H121 -> 0.7607 | I7: ='Por año'!I121 -> 6.656 | J7: ='Por año'!K102 -> 0
A8: ='Por año'!A140 -> 18-19 | B8: ='Por año'!B140 -> Mate | C8: ='Por año'!C140 -> 17 | D8: =CONCATENATE(A8,"(",C8,")") -> 18-19(17) | E8: ='Por año'!E140 -> 0.8824 | F8: ='Por año'!F140 -> 6.868 | G8: ='Por año'!G140 -> 7.38 | H8: ='Por año'!H140 -> 0.7366 | I8: ='Por año'!I140 -> 6.244 | J8: ='Por año'!K121 -> 0
A9: ='Por año'!A159 -> 17-18 | B9: ='Por año'!B159 -> Mate | C9: ='Por año'!C159 -> 18 | D9: =CONCATENATE(A9,"(",C9,")") -> 17-18(18) | E9: ='Por año'!E159 -> 0.3889 | F9: ='Por año'!F159 -> 5.042 | G9: ='Por año'!G159 -> 6.78 | H9: ='Por año'!H159 -> 0.6645 | I9: ='Por año'!I159 -> 5.701 | J9: ='Por año'!K140 -> 0
A10: ='Por año'!A178 -> 16-17 | B10: ='Por año'!B178 -> Mate | C10: ='Por año'!C178 -> 20 | D10: =CONCATENATE(A10,"(",C10,")") -> 16-17(20) | E10: ='Por año'!E178 -> 0.8 | F10: ='Por año'!F178 -> 6.912 | G10: ='Por año'!G178 -> 7 | H10: ='Por año'!H178 -> 0.7602 | I10: ='Por año'!I178 -> 6.498 | J10: ='Por año'!K159 -> 0
A12: ='Por año'!A191 -> 0 | B12: ='Por año'!B191 -> 0 | C12: ='Por año'!C191 -> 0 | E12: ='Por año'!E191 -> 0 | F12: ='Por año'!F191 -> 0 | H12: ='Por año'!H191 -> 0 | I12: ='Por año'!I191 -> 0 | J12: ='Por año'!K172 -> 0
A13: ='Por año'!A192 -> 0 | B13: ='Por año'!B192 -> 0 | C13: ='Por año'!C192 -> 0 | E13: ='Por año'!E192 -> 0 | F13: ='Por año'!F192 -> 0 | H13: ='Por año'!H192 -> 0 | I13: ='Por año'!I192 -> 0 | J13: ='Por año'!K173 -> 0
A14: ='Por año'!A193 -> 0 | B14: ='Por año'!B193 -> 0 | C14: ='Por año'!C193 -> 0 | E14: ='Por año'!E193 -> 0 | F14: ='Por año'!F193 -> 0 | H14: ='Por año'!H193 -> 0 | I14: ='Por año'!I193 -> 0 | J14: ='Por año'!K174 -> 0
A15: ='Por año'!A194 -> 0 | B15: ='Por año'!B194 -> 0 | C15: ='Por año'!C194 -> 0 | E15: ='Por año'!E194 -> 0 | F15: ='Por año'!F194 -> 0 | H15: ='Por año'!H194 -> 0 | I15: ='Por año'!I194 -> 0 | J15: ='Por año'!K175 -> 0
A16: ='Por año'!A195 -> 0 | B16: ='Por año'!B195 -> 0 | C16: ='Por año'!C195 -> 0 | E16: ='Por año'!E195 -> 0 | F16: ='Por año'!F195 -> 0 | H16: ='Por año'!H195 -> 0 | I16: ='Por año'!I195 -> 0 | J16: ='Por año'!K176 -> 0
A17: ='Por año'!A196 -> 0 | B17: ='Por año'!B196 -> 0 | C17: ='Por año'!C196 -> 0 | E17: ='Por año'!E196 -> 0 | F17: ='Por año'!F196 -> 0 | H17: ='Por año'!H196 -> 0 | I17: ='Por año'!I196 -> 0 | J17: ='Por año'!K177 -> 0
A18: ='Por año'!A197 -> 0 | B18: ='Por año'!B197 -> 0 | C18: ='Por año'!C197 -> 0 | E18: ='Por año'!E197 -> 0 | F18: ='Por año'!F197 -> 0 | H18: ='Por año'!H197 -> 0 | I18: ='Por año'!I197 -> 0 | J18: ='Por año'!K178 -> 0
A19: ='Por año'!A198 -> 0 | B19: ='Por año'!B198 -> 0 | C19: ='Por año'!C198 -> 0 | E19: ='Por año'!E198 -> 0 | F19: ='Por año'!F198 -> 0 | H19: ='Por año'!H198 -> 0 | I19: ='Por año'!I198 -> 0 | J19: ='Por año'!K179 -> 0
A20: ='Por año'!A199 -> 0 | B20: ='Por año'!B199 -> 0 | C20: ='Por año'!C199 -> 0 | E20: ='Por año'!E199 -> 0 | F20: ='Por año'!F199 -> 0 | H20: ='Por año'!H199 -> 0 | I20: ='Por año'!I199 -> 0 | J20: ='Por año'!K180 -> 0
A21: ='Por año'!A200 -> 0 | B21: ='Por año'!B200 -> 0 | C21: ='Por año'!C200 -> 0 | E21: ='Por año'!E200 -> 0 | F21: ='Por año'!F200 -> 0 | H21: ='Por año'!H200 -> 0 | I21: ='Por año'!I200 -> 0 | J21: ='Por año'!K181 -> 0
A22: ='Por año'!A201 -> 0 | B22: ='Por año'!B201 -> 0 | C22: ='Por año'!C201 -> 0 | E22: ='Por año'!E201 -> 0 | F22: ='Por año'!F201 -> 0 | H22: ='Por año'!H201 -> 0 | I22: ='Por año'!I201 -> 0 | J22: ='Por año'!K182 -> 0
A23: ='Por año'!A202 -> 0 | B23: ='Por año'!B202 -> 0 | C23: ='Por año'!C202 -> 0 | E23: ='Por año'!E202 -> 0 | F23: ='Por año'!F202 -> 0 | H23: ='Por año'!H202 -> 0 | I23: ='Por año'!I202 -> 0 | J23: ='Por año'!K183 -> 0
... A31: ='Por año'!A210 -> 0 | B31: ='Por año'!B210 -> 0 | C31: ='Por año'!C210 -> 0 | E31: ='Por año'!E210 -> 0 | F31: ='Por año'!F210 -> 0 | H31: ='Por año'!H210 -> 0 | I31: ='Por año'!I210 -> 0 | J31: ='Por año'!K191 -> 0

Sheet Mate CCSS II
A1: ='Por año'!A117 -> 0 | B1: ='Por año'!B117 -> Materia | C1: ='Por año'!C117 -> Presentados | E1: ='Por año'!E117 -> % LSG | F1: ='Por año'!F117 -> NM LSG EvAU | G1: ='Por año'!G117 -> NM LSG Cole | H1: ='Por año'!H117 -> % UC3M | I1: ='Por año'!I117 -> NM UC3M | J1: ='Por año'!K98 -> 0
A2: ='Por año'!A27 -> 24-25 | B2: ='Por año'!B45 -> Mate | C2: ='Por año'!C27 -> 7 | D2: =CONCATENATE(A2,"(",C2,")") -> 24-25(7) | E2: ='Por año'!E27 -> 1 | F2: ='Por año'!F27 -> 6.36 | G2: ='Por año'!G27 -> 6.43 | H2: ='Por año'!H27 -> 0.5923 | I2: ='Por año'!I27 -> 5.22
A3: ='Por año'!A46 -> 23-24 | B3: ='Por año'!B46 -> Mate CCSS | C3: ='Por año'!C46 -> 9 | D3: =CONCATENATE(A3,"(",C3,")") -> 23-24(9) | E3: ='Por año'!E46 -> 1 | F3: ='Por año'!F46 -> 7.04 | G3: ='Por año'!G46 -> 6.11 | H3: ='Por año'!H46 -> 0.7939 | I3: ='Por año'!I46 -> 6.72
A4: ='Por año'!A65 -> 22-23 | B4: ='Por año'!B65 -> Mate CCSS | C4: ='Por año'!C65 -> 18 | D4: =CONCATENATE(A4,"(",C4,")") -> 22-23(18) | E4: ='Por año'!E65 -> 1 | F4: ='Por año'!F65 -> 7.71 | G4: ='Por año'!G65 -> 7.11 | H4: ='Por año'!H65 -> 0.8038 | I4: ='Por año'!I65 -> 6.79
A5: ='Por año'!A84 -> 21-22 | B5: ='Por año'!B84 -> Mate CCSS | C5: ='Por año'!C84 -> 20 | D5: =CONCATENATE(A5,"(",C5,")") -> 21-22(20) | E5: ='Por año'!E84 -> 0.8 | F5: ='Por año'!F84 -> 6.2 | G5: ='Por año'!G84 -> 6.68 | H5: ='Por año'!H84 -> 0.7099 | I5: ='Por año'!I84 -> 5.93
A6: ='Por año'!A103 -> 20-21 | B6: ='Por año'!B103 -> Mate CCSS | C6: ='Por año'!C103 -> 19 | D6: =CONCATENATE(A6,"(",C6,")") -> 20-21(19) | E6: ='Por año'!E103 -> 0.8421 | F6: ='Por año'!F103 -> 6.87 | G6: ='Por año'!G103 -> 6.89 | H6: ='Por año'!H103 -> 0.6568 | I6: ='Por año'!I103 -> 5.83
A7: ='Por año'!A122 -> 19-20 | B7: ='Por año'!B122 -> Mate CCSS | C7: ='Por año'!C122 -> 20 | D7: =CONCATENATE(A7,"(",C7,")") -> 19-20(20) | E7: ='Por año'!E122 -> 0.85 | F7: ='Por año'!F122 -> 6.388 | G7: ='Por año'!G122 -> 7.72 | H7: ='Por año'!H122 -> 0.5999 | I7: ='Por año'!I122 -> 5.331
A8: ='Por año'!A141 -> 18-19 | B8: ='Por año'!B141 -> Mate CCSS | C8: ='Por año'!C141 -> 20 | D8: =CONCATENATE(A8,"(",C8,")") -> 18-19(20) | E8: ='Por año'!E141 -> 0.7 | F8: ='Por año'!F141 -> 5.875 | G8: ='Por año'!G141 -> 6 | H8: ='Por año'!H141 -> 0.5549 | I8: ='Por año'!I141 -> 5.262
A9: ='Por año'!A160 -> 17-18 | B9: ='Por año'!B160 -> Mate CCSS | C9: ='Por año'!C160 -> 15 | D9: =CONCATENATE(A9,"(",C9,")") -> 17-18(15) | E9: ='Por año'!E160 -> 1 | F9: ='Por año'!F160 -> 7.35 | G9: ='Por año'!G160 -> 6.19 | H9: ='Por año'!H160 -> 0.8323 | I9: ='Por año'!I160 -> 7.046
A10: ='Por año'!A179 -> 16-17 | B10: ='Por año'!B179 -> Mate CCSS | C10: ='Por año'!C179 -> 16 | D10: =CONCATENATE(A10,"(",C10,")") -> 16-17(16) | E10: ='Por año'!E179 -> 0.875 | F10: ='Por año'!F179 -> 7.172 | G10: ='Por año'!G179 -> 7 | H10: ='Por año'!H179 -> 0.5865 | I10: ='Por año'!I179 -> 5.216 | J10: ='Por año'!K170 -> 0
A11: ='Por año'!A191 -> 0 | B11: ='Por año'!B191 -> 0 | C11: ='Por año'!C191 -> 0 | E11: ='Por año'!E191 -> 0 | F11: ='Por año'!F191 -> 0 | H11: ='Por año'!H191 -> 0 | I11: ='Por año'!I191 -> 0 | J11: ='Por año'!K172 -> 0
A12: ='Por año'!A192 -> 0 | B12: ='Por año'!B192 -> 0 | C12: ='Por año'!C192 -> 0 | E12: ='Por año'!E192 -> 0 | F12: ='Por año'!F192 -> 0 | H12: ='Por año'!H192 -> 0 | I12: ='Por año'!I192 -> 0 | J12: ='Por año'!K173 -> 0
A13: ='Por año'!A193 -> 0 | B13: ='Por año'!B193 -> 0 | C13: ='Por año'!C193 -> 0 | E13: ='Por año'!E193 -> 0 | F13: ='Por año'!F193 -> 0 | H13: ='Por año'!H193 -> 0 | I13: ='Por año'!I193 -> 0 | J13: ='Por año'!K174 -> 0
A14: ='Por año'!A194 -> 0 | B14: ='Por año'!B194 -> 0 | C14: ='Por año'!C194 -> 0 | E14: ='Por año'!E194 -> 0 | F14: ='Por año'!F194 -> 0 | H14: ='Por año'!H194 -> 0 | I14: ='Por año'!I194 -> 0 | J14: ='Por año'!K175 -> 0
A15: ='Por año'!A195 -> 0 | B15: ='Por año'!B195 -> 0 | C15: ='Por año'!C195 -> 0 | E15: ='Por año'!E195 -> 0 | F15: ='Por año'!F195 -> 0 | H15: ='Por año'!H195 -> 0 | I15: ='Por año'!I195 -> 0 | J15: ='Por año'!K176 -> 0
A16: ='Por año'!A196 -> 0 | B16: ='Por año'!B196 -> 0 | C16: ='Por año'!C196 -> 0 | E16: ='Por año'!E196 -> 0 | F16: ='Por año'!F196 -> 0 | H16: ='Por año'!H196 -> 0 | I16: ='Por año'!I196 -> 0 | J16: ='Por año'!K177 -> 0
A17: ='Por año'!A197 -> 0 | B17: ='Por año'!B197 -> 0 | C17: ='Por año'!C197 -> 0 | E17: ='Por año'!E197 -> 0 | F17: ='Por año'!F197 -> 0 | H17: ='Por año'!H197 -> 0 | I17: ='Por año'!I197 -> 0 | J17: ='Por año'!K178 -> 0
A18: ='Por año'!A198 -> 0 | B18: ='Por año'!B198 -> 0 | C18: ='Por año'!C198 -> 0 | E18: ='Por año'!E198 -> 0 | F18: ='Por año'!F198 -> 0 | H18: ='Por año'!H198 -> 0 | I18: ='Por año'!I198 -> 0 | J18: ='Por año'!K179 -> 0
A19: ='Por año'!A199 -> 0 | B19: ='Por año'!B199 -> 0 | C19: ='Por año'!C199 -> 0 | E19: ='Por año'!E199 -> 0 | F19: ='Por año'!F199 -> 0 | H19: ='Por año'!H199 -> 0 | I19: ='Por año'!I199 -> 0 | J19: ='Por año'!K180 -> 0
A20: ='Por año'!A200 -> 0 | B20: ='Por año'!B200 -> 0 | C20: ='Por año'!C200 -> 0 | E20: ='Por año'!E200 -> 0 | F20: ='Por año'!F200 -> 0 | H20: ='Por año'!H200 -> 0 | I20: ='Por año'!I200 -> 0 | J20: ='Por año'!K181 -> 0
A21: ='Por año'!A201 -> 0 | B21: ='Por año'!B201 -> 0 | C21: ='Por año'!C201 -> 0 | E21: ='Por año'!E201 -> 0 | F21: ='Por año'!F201 -> 0 | H21: ='Por año'!H201 -> 0 | I21: ='Por año'!I201 -> 0 | J21: ='Por año'!K182 -> 0
A22: ='Por año'!A202 -> 0 | B22: ='Por año'!B202 -> 0 | C22: ='Por año'!C202 -> 0 | E22: ='Por año'!E202 -> 0 | F22: ='Por año'!F202 -> 0 | H22: ='Por año'!H202 -> 0 | I22: ='Por año'!I202 -> 0 | J22: ='Por año'!K183 -> 0
... A30: ='Por año'!A210 -> 0 | B30: ='Por año'!B210 -> 0 | C30: ='Por año'!C210 -> 0 | E30: ='Por año'!E210 -> 0 | F30: ='Por año'!F210 -> 0 | H30: ='Por año'!H210 -> 0 | I30: ='Por año'!I210 -> 0 | J30: ='Por año'!K191 -> 0

Sheet Física
A1: ='Por año'!A117 -> 0 | B1: ='Por año'!B117 -> Materia | C1: ='Por año'!C117 -> Presentados | E1: ='Por año'!E117 -> % LSG | F1: ='Por año'!F117 -> NM LSG EvAU | G1: ='Por año'!G117 -> NM LSG Cole | H1: ='Por año'!H117 -> % UC3M | I1: ='Por año'!I117 -> NM UC3M | J1: ='Por año'!K98 -> 0
A2: ='Por año'!A28 -> 24-25 | B2: ='Por año'!B28 -> Física | C2: ='Por año'!C28 -> 20 | D2: =CONCATENATE(A2,"(",C2,")") -> 24-25(20) | E2: ='Por año'!E28 -> 0.3 | F2: ='Por año'!F28 -> 4.43 | G2: ='Por año'!G28 -> 6.65 | H2: ='Por año'!H28 -> 0.5504 | I2: ='Por año'!I28 -> 5.3
A3: ='Por año'!A47 -> 23-24 | B3: ='Por año'!B47 -> Física | C3: ='Por año'!C47 -> 26 | D3: =CONCATENATE(A3,"(",C3,")") -> 23-24(26) | E3: ='Por año'!E47 -> 0.8148 | F3: ='Por año'!F47 -> 6.21 | G3: ='Por año'!G47 -> 7 | H3: ='Por año'!H47 -> 0.7849 | I3: ='Por año'!I47 -> 6.45
A4: ='Por año'!A66 -> 22-23 | B4: ='Por año'!B66 -> Física | C4: ='Por año'!C66 -> 21 | D4: =CONCATENATE(A4,"(",C4,")") -> 22-23(21) | E4: ='Por año'!E66 -> 0.9091 | F4: ='Por año'!F66 -> 7.27 | G4: ='Por año'!G66 -> 7.2 | H4: ='Por año'!H66 -> 0.8113 | I4: ='Por año'!I66 -> 6.85
A5: ='Por año'!A85 -> 21-22 | B5: ='Por año'!B85 -> Física | C5: ='Por año'!C85 -> 25 | D5: =CONCATENATE(A5,"(",C5,")") -> 21-22(25) | E5: ='Por año'!E85 -> 0.72 | F5: ='Por año'!F85 -> 5.72 | G5: ='Por año'!G85 -> 7.48 | H5: ='Por año'!H85 -> 0.6059 | I5: ='Por año'!I85 -> 5.52
A6: ='Por año'!A104 -> 20-21 | B6: ='Por año'!B104 -> Física | C6: ='Por año'!C104 -> 24 | D6: =CONCATENATE(A6,"(",C6,")") -> 20-21(24) | E6: ='Por año'!E104 -> 0.7917 | F6: ='Por año'!F104 -> 6.98 | G6: ='Por año'!G104 -> 7.77 | H6: ='Por año'!H104 -> 0.7789 | I6: ='Por año'!I104 -> 6.92
A7: ='Por año'!A123 -> 19-20 | B7: ='Por año'!B123 -> Física | C7: ='Por año'!C123 -> 28 | D7: =CONCATENATE(A7,"(",C7,")") -> 19-20(28) | E7: ='Por año'!E123 -> 0.7778 | F7: ='Por año'!F123 -> 7.046 | G7: ='Por año'!G123 -> 7.3 | H7: ='Por año'!H123 -> 0.8166 | I7: ='Por año'!I123 -> 7.081
A8: ='Por año'!A142 -> 18-19 | B8: ='Por año'!B142 -> Física | C8: ='Por año'!C142 -> 17 | D8: =CONCATENATE(A8,"(",C8,")") -> 18-19(17) | E8: ='Por año'!E142 -> 0.7647 | F8: ='Por año'!F142 -> 6.588 | G8: ='Por año'!G142 -> 7.62 | H8: ='Por año'!H142 -> 0.528 | I8: ='Por año'!I142 -> 4.948
A9: ='Por año'!A161 -> 17-18 | B9: ='Por año'!B161 -> Física | C9: ='Por año'!C161 -> 15 | D9: =CONCATENATE(A9,"(",C9,")") -> 17-18(15) | E9: ='Por año'!E161 -> 0.5333 | F9: ='Por año'!F161 -> 5.95 | G9: ='Por año'!G161 -> 7.35 | H9: ='Por año'!H161 -> 0.5652 | I9: ='Por año'!I161 -> 5.255
A10: ='Por año'!A180 -> 16-17 | B10: ='Por año'!B180 -> Física | C10: ='Por año'!C180 -> 18 | D10: =CONCATENATE(A10,"(",C10,")") -> 16-17(18) | E10: ='Por año'!E180 -> 0.7778 | F10: ='Por año'!F180 -> 6.458 | G10: ='Por año'!G180 -> 6.86 | H10: ='Por año'!H180 -> 0.667 | I10: ='Por año'!I180 -> 5.722 | J10: ='Por año'!K172 -> 0
A11: ='Por año'!A192 -> 0 | B11: ='Por año'!B192 -> 0 | C11: ='Por año'!C192 -> 0 | E11: ='Por año'!E192 -> 0 | F11: ='Por año'!F192 -> 0 | H11: ='Por año'!H192 -> 0 | I11: ='Por año'!I192 -> 0 | J11: ='Por año'!K173 -> 0
A12: ='Por año'!A193 -> 0 | B12: ='Por año'!B193 -> 0 | C12: ='Por año'!C193 -> 0 | E12: ='Por año'!E193 -> 0 | F12: ='Por año'!F193 -> 0 | H12: ='Por año'!H193 -> 0 | I12: ='Por año'!I193 -> 0 | J12: ='Por año'!K174 -> 0
A13: ='Por año'!A194 -> 0 | B13: ='Por año'!B194 -> 0 | C13: ='Por año'!C194 -> 0 | E13: ='Por año'!E194 -> 0 | F13: ='Por año'!F194 -> 0 | H13: ='Por año'!H194 -> 0 | I13: ='Por año'!I194 -> 0 | J13: ='Por año'!K175 -> 0
A14: ='Por año'!A195 -> 0 | B14: ='Por año'!B195 -> 0 | C14: ='Por año'!C195 -> 0 | E14: ='Por año'!E195 -> 0 | F14: ='Por año'!F195 -> 0 | H14: ='Por año'!H195 -> 0 | I14: ='Por año'!I195 -> 0 | J14: ='Por año'!K176 -> 0
A15: ='Por año'!A196 -> 0 | B15: ='Por año'!B196 -> 0 | C15: ='Por año'!C196 -> 0 | E15: ='Por año'!E196 -> 0 | F15: ='Por año'!F196 -> 0 | H15: ='Por año'!H196 -> 0 | I15: ='Por año'!I196 -> 0 | J15: ='Por año'!K177 -> 0
A16: ='Por año'!A197 -> 0 | B16: ='Por año'!B197 -> 0 | C16: ='Por año'!C197 -> 0 | E16: ='Por año'!E197 -> 0 | F16: ='Por año'!F197 -> 0 | H16: ='Por año'!H197 -> 0 | I16: ='Por año'!I197 -> 0 | J16: ='Por año'!K178 -> 0
A17: ='Por año'!A198 -> 0 | B17: ='Por año'!B198 -> 0 | C17: ='Por año'!C198 -> 0 | E17: ='Por año'!E198 -> 0 | F17: ='Por año'!F198 -> 0 | H17: ='Por año'!H198 -> 0 | I17: ='Por año'!I198 -> 0 | J17: ='Por año'!K179 -> 0
A18: ='Por año'!A199 -> 0 | B18: ='Por año'!B199 -> 0 | C18: ='Por año'!C199 -> 0 | E18: ='Por año'!E199 -> 0 | F18: ='Por año'!F199 -> 0 | H18: ='Por año'!H199 -> 0 | I18: ='Por año'!I199 -> 0 | J18: ='Por año'!K180 -> 0
A19: ='Por año'!A200 -> 0 | B19: ='Por año'!B200 -> 0 | C19: ='Por año'!C200 -> 0 | E19: ='Por año'!E200 -> 0 | F19: ='Por año'!F200 -> 0 | H19: ='Por año'!H200 -> 0 | I19: ='Por año'!I200 -> 0 | J19: ='Por año'!K181 -> 0
A20: ='Por año'!A201 -> 0 | B20: ='Por año'!B201 -> 0 | C20: ='Por año'!C201 -> 0 | E20: ='Por año'!E201 -> 0 | F20: ='Por año'!F201 -> 0 | H20: ='Por año'!H201 -> 0 | I20: ='Por año'!I201 -> 0 | J20: ='Por año'!K182 -> 0
A21: ='Por año'!A202 -> 0 | B21: ='Por año'!B202 -> 0 | C21: ='Por año'!C202 -> 0 | E21: ='Por año'!E202 -> 0 | F21: ='Por año'!F202 -> 0 | H21: ='Por año'!H202 -> 0 | I21: ='Por año'!I202 -> 0 | J21: ='Por año'!K183 -> 0
A22: ='Por año'!A203 -> 0 | B22: ='Por año'!B203 -> 0 | C22: ='Por año'!C203 -> 0 | E22: ='Por año'!E203 -> 0 | F22: ='Por año'!F203 -> 0 | H22: ='Por año'!H203 -> 0 | I22: ='Por año'!I203 -> 0 | J22: ='Por año'!K184 -> 0
... A29: ='Por año'!A210 -> 0 | B29: ='Por año'!B210 -> 0 | C29: ='Por año'!C210 -> 0 | E29: ='Por año'!E210 -> 0 | F29: ='Por año'!F210 -> 0 | H29: ='Por año'!H210 -> 0 | I29: ='Por año'!I210 -> 0 | J29: ='Por año'!K191 -> 0

Sheet Química
A1: ='Por año'!A117 -> 0 | B1: ='Por año'!B117 -> Materia | C1: ='Por año'!C117 -> Presentados | E1: ='Por año'!E117 -> % LSG | F1: ='Por año'!F117 -> NM LSG EvAU | G1: ='Por año'!G117 -> NM LSG Cole | H1: ='Por año'!H117 -> % UC3M | I1: ='Por año'!I117 -> NM UC3M | J1: ='Por año'!K98 -> 0
A2: ='Por año'!A29 -> 24-25 | B2: ='Por año'!B29 -> Química | C2: ='Por año'!C29 -> 15 | D2: =CONCATENATE(A2,"(",C2,")") -> 24-25(15) | E2: ='Por año'!E29 -> 0.8667 | F2: ='Por año'!F29 -> 6.68 | G2: ='Por año'!G29 -> 7.05 | H2: ='Por año'!H29 -> 0.7366 | I2: ='Por año'!I29 -> 6.11
A3: ='Por año'!A48 -> 23-24 | B3: ='Por año'!B48 -> Química | C3: ='Por año'!C48 -> 28 | D3: =CONCATENATE(A3,"(",C3,")") -> 23-24(28) | E3: ='Por año'!E48 -> 0.7857 | F3: ='Por año'!F48 -> 6.1 | G3: ='Por año'!G48 -> 7.46 | H3: ='Por año'!H48 -> 0.7797 | I3: ='Por año'!I48 -> 6.48
A4: ='Por año'!A67 -> 22-23 | B4: ='Por año'!B67 -> Química | C4: ='Por año'!C67 -> 13 | D4: =CONCATENATE(A4,"(",C4,")") -> 22-23(13) | E4: ='Por año'!E67 -> 0.7143 | F4: ='Por año'!F67 -> 6.68 | G4: ='Por año'!G67 -> 6.68 | H4: ='Por año'!H67 -> 0.8145 | I4: ='Por año'!I67 -> 6.81
A5: ='Por año'!A86 -> 21-22 | B5: ='Por año'!B86 -> Química | C5: ='Por año'!C86 -> 19 | D5: =CONCATENATE(A5,"(",C5,")") -> 21-22(19) | E5: ='Por año'!E86 -> 0.7895 | F5: ='Por año'!F86 -> 7.01 | G5: ='Por año'!G86 -> 7.62 | H5: ='Por año'!H86 -> 0.8481 | I5: ='Por año'!I86 -> 7.06
A6: ='Por año'!A105 -> 20-21 | B6: ='Por año'!B105 -> Química | C6: ='Por año'!C105 -> 27 | D6: =CONCATENATE(A6,"(",C6,")") -> 20-21(27) | E6: ='Por año'!E105 -> 0.963 | F6: ='Por año'!F105 -> 7.71 | G6: ='Por año'!G105 -> 7.65 | H6: ='Por año'!H105 -> 0.9031 | I6: ='Por año'!I105 -> 7.6
A7: ='Por año'!A124 -> 19-20 | B7: ='Por año'!B124 -> Química | C7: ='Por año'!C124 -> 22 | D7: =CONCATENATE(A7,"(",C7,")") -> 19-20(22) | E7: ='Por año'!E124 -> 0.6818 | F7: ='Por año'!F124 -> 6.011 | G7: ='Por año'!G124 -> 7.37 | H7: ='Por año'!H124 -> 0.6973 | I7: ='Por año'!I124 -> 6.104
A8: ='Por año'!A143 -> 18-19 | B8: ='Por año'!B143 -> Química | C8: ='Por año'!C143 -> 14 | D8: =CONCATENATE(A8,"(",C8,")") -> 18-19(14) | E8: ='Por año'!E143 -> 1 | F8: ='Por año'!F143 -> 7.179 | G8: ='Por año'!G143 -> 7.52 | H8: ='Por año'!H143 -> 0.7729 | I8: ='Por año'!I143 -> 6.604
A9: ='Por año'!A162 -> 17-18 | B9: ='Por año'!B162 -> Química | C9: ='Por año'!C162 -> 14 | D9: =CONCATENATE(A9,"(",C9,")") -> 17-18(14) | E9: ='Por año'!E162 -> 0.8571 | F9: ='Por año'!F162 -> 6.393 | G9: ='Por año'!G162 -> 6.57 | H9: ='Por año'!H162 -> 0.7198 | I9: ='Por año'!I162 -> 6.094
A10: ='Por año'!A181 -> 16-17 | B10: ='Por año'!B181 -> Química | C10: ='Por año'!C181 -> 11 | D10: =CONCATENATE(A10,"(",C10,")") -> 16-17(11) | E10: ='Por año'!E181 -> 0.5455 | F10: ='Por año'!F181 -> 4.523 | G10: ='Por año'!G181 -> 6.95 | H10: ='Por año'!H181 -> 0.5361 | I10: ='Por año'!I181 -> 4.932
A11: ='Por año'!A192 -> 0 | B11: ='Por año'!B192 -> 0 | C11: ='Por año'!C192 -> 0 | E11: ='Por año'!E192 -> 0 | F11: ='Por año'!F192 -> 0 | H11: ='Por año'!H192 -> 0 | I11: ='Por año'!I192 -> 0 | J11: ='Por año'!K173 -> 0
A12: ='Por año'!A193 -> 0 | B12: ='Por año'!B193 -> 0 | C12: ='Por año'!C193 -> 0 | E12: ='Por año'!E193 -> 0 | F12: ='Por año'!F193 -> 0 | H12: ='Por año'!H193 -> 0 | I12: ='Por año'!I193 -> 0 | J12: ='Por año'!K174 -> 0
A13: ='Por año'!A194 -> 0 | B13: ='Por año'!B194 -> 0 | C13: ='Por año'!C194 -> 0 | E13: ='Por año'!E194 -> 0 | F13: ='Por año'!F194 -> 0 | H13: ='Por año'!H194 -> 0 | I13: ='Por año'!I194 -> 0 | J13: ='Por año'!K175 -> 0
A14: ='Por año'!A195 -> 0 | B14: ='Por año'!B195 -> 0 | C14: ='Por año'!C195 -> 0 | E14: ='Por año'!E195 -> 0 | F14: ='Por año'!F195 -> 0 | H14: ='Por año'!H195 -> 0 | I14: ='Por año'!I195 -> 0 | J14: ='Por año'!K176 -> 0
A15: ='Por año'!A196 -> 0 | B15: ='Por año'!B196 -> 0 | C15: ='Por año'!C196 -> 0 | E15: ='Por año'!E196 -> 0 | F15: ='Por año'!F196 -> 0 | H15: ='Por año'!H196 -> 0 | I15: ='Por año'!I196 -> 0 | J15: ='Por año'!K177 -> 0
A16: ='Por año'!A197 -> 0 | B16: ='Por año'!B197 -> 0 | C16: ='Por año'!C197 -> 0 | E16: ='Por año'!E197 -> 0 | F16: ='Por año'!F197 -> 0 | H16: ='Por año'!H197 -> 0 | I16: ='Por año'!I197 -> 0 | J16: ='Por año'!K178 -> 0
A17: ='Por año'!A198 -> 0 | B17: ='Por año'!B198 -> 0 | C17: ='Por año'!C198 -> 0 | E17: ='Por año'!E198 -> 0 | F17: ='Por año'!F198 -> 0 | H17: ='Por año'!H198 -> 0 | I17: ='Por año'!I198 -> 0 | J17: ='Por año'!K179 -> 0
A18: ='Por año'!A199 -> 0 | B18: ='Por año'!B199 -> 0 | C18: ='Por año'!C199 -> 0 | E18: ='Por año'!E199 -> 0 | F18: ='Por año'!F199 -> 0 | H18: ='Por año'!H199 -> 0 | I18: ='Por año'!I199 -> 0 | J18: ='Por año'!K180 -> 0
A19: ='Por año'!A200 -> 0 | B19: ='Por año'!B200 -> 0 | C19: ='Por año'!C200 -> 0 | E19: ='Por año'!E200 -> 0 | F19: ='Por año'!F200 -> 0 | H19: ='Por año'!H200 -> 0 | I19: ='Por año'!I200 -> 0 | J19: ='Por año'!K181 -> 0
A20: ='Por año'!A201 -> 0 | B20: ='Por año'!B201 -> 0 | C20: ='Por año'!C201 -> 0 | E20: ='Por año'!E201 -> 0 | F20: ='Por año'!F201 -> 0 | H20: ='Por año'!H201 -> 0 | I20: ='Por año'!I201 -> 0 | J20: ='Por año'!K182 -> 0
A21: ='Por año'!A202 -> 0 | B21: ='Por año'!B202 -> 0 | C21: ='Por año'!C202 -> 0 | E21: ='Por año'!E202 -> 0 | F21: ='Por año'!F202 -> 0 | H21: ='Por año'!H202 -> 0 | I21: ='Por año'!I202 -> 0 | J21: ='Por año'!K183 -> 0
A22: ='Por año'!A203 -> 0 | B22: ='Por año'!B203 -> 0 | C22: ='Por año'!C203 -> 0 | E22: ='Por año'!E203 -> 0 | F22: ='Por año'!F203 -> 0 | H22: ='Por año'!H203 -> 0 | I22: ='Por año'!I203 -> 0 | J22: ='Por año'!K184 -> 0
... A29: ='Por año'!A210 -> 0 | B29: ='Por año'!B210 -> 0 | C29: ='Por año'!C210 -> 0 | E29: ='Por año'!E210 -> 0 | F29: ='Por año'!F210 -> 0 | H29: ='Por año'!H210 -> 0 | I29: ='Por año'!I210 -> 0 | J29: ='Por año'!K191 -> 0

Sheet Biología
A1: ='Por año'!A117 -> 0 | B1: ='Por año'!B117 -> Materia | C1: ='Por año'!C117 -> Presentados | E1: ='Por año'!E117 -> % LSG | F1: ='Por año'!F117 -> NM LSG EvAU | G1: ='Por año'!G117 -> NM LSG Cole | H1: ='Por año'!H117 -> % UC3M | I1: ='Por año'!I117 -> NM UC3M | J1: ='Por año'!K98 -> 0
